<?xml version="1.0"?>
<robot xmlns:xacro="http://www.ros.org/wiki/xacro">

    <xacro:property name="base_radius" value="0.15"/>
    <xacro:property name="base_length" value="0.1"/>
    <xacro:property name="wheel_radius" value="0.05"/>
    <xacro:property name="wheel_thickness" value="0.02"/>

    <link name="base_link">
        <visual>
            <geometry>
                <cylinder radius="${base_radius}" length="${base_length}"/>
            </geometry>
            <material name="blue">
                <color rgba="0 0 0.8 1"/>
            </material>
        </visual>
        <collision>
            <geometry>
                <cylinder radius="${base_radius}" length="${base_length}"/>
            </geometry>
        </collision>
        <inertial>
            <mass value="2.0"/>
            <inertia ixx="0.02" ixy="0" ixz="0" iyy="0.02" iyz="0" izz="0.02"/>
        </inertial>
    </link>

    <link name="left_wheel">
        <visual>
            <geometry>
                <cylinder radius="${wheel_radius}" length="${wheel_thickness}"/>
            </geometry>
            <material name="black">
                <color rgba="0 0 0 1"/>
            </material>
        </visual>
        <collision>
            <geometry>
                <cylinder radius="${wheel_radius}" length="${wheel_thickness}"/>
            </geometry>
        </collision>
        <inertial>
            <mass value="0.2"/>
            <inertia ixx="0.001" ixy="0" ixz="0" iyy="0.001" iyz="0" izz="0.001"/>
        </inertial>
    </link>

    <joint name="left_wheel_joint" type="continuous">
        <parent link="base_link"/>
        <child link="left_wheel"/>
        <origin xyz="0 0.17 -0.05" rpy="-1.5708 0 0"/>
        <axis xyz="0 0 1"/>
    </joint>

    <link name="right_wheel">
        <visual>
            <geometry>
                <cylinder radius="${wheel_radius}" length="${wheel_thickness}"/>
            </geometry>
            <material name="black"/>
        </visual>
        <collision>
            <geometry>
                <cylinder radius="${wheel_radius}" length="${wheel_thickness}"/>
            </geometry>
        </collision>
        <inertial>
            <mass value="0.2"/>
            <inertia ixx="0.001" ixy="0" ixz="0" iyy="0.001" iyz="0" izz="0.001"/>
        </inertial>
    </link>

    <joint name="right_wheel_joint" type="continuous">
        <parent link="base_link"/>
        <child link="right_wheel"/>
        <origin xyz="0 -0.17 -0.05" rpy="-1.5708 0 0"/>
        <axis xyz="0 0 1"/>
    </joint>

    <link name="caster_wheel">
        <visual>
            <geometry>
                <sphere radius="0.05"/>
            </geometry>
            <material name="white">
                <color rgba="1 1 1 1"/>
            </material>
        </visual>
        <collision>
            <geometry>
                <sphere radius="0.05"/>
            </geometry>
        </collision>
        <inertial>
            <mass value="0.1"/>
            <inertia ixx="0.0001" ixy="0" ixz="0" iyy="0.0001" iyz="0" izz="0.0001"/>
        </inertial>
    </link>

    <joint name="caster_joint" type="fixed">
        <parent link="base_link"/>
        <child link="caster_wheel"/>
        <origin xyz="0.1 0 -0.05" rpy="0 0 0"/>
    </joint>

</robot>